<mujoco model="ant">
  <compiler angle="degree" coordinate="local" inertiafromgeom="true"/>
  <option integrator="RK4" timestep="0.004"/>
  <size nconmax="1000" njmax="2000"/>

  <custom>
    <numeric data="0.0 0.0 0.35 1.0 0.0 0.0 0.0 0.0 1.0 0.0 -1.0 0.0 -1.0 0.0 1.0" name="init_qpos"/>
  </custom>

  <default>
    <joint armature="1" damping="1" limited="true"/>
    <geom conaffinity="0" condim="3" density="5.0" friction="1 0.5 0.5" margin="0.01" rgba="0.8 0.6 0.4 1"/>
  </default>
  <asset>
    <texture name="skybox" type="skybox" builtin="gradient" rgb1=".4 .6 .8" rgb2="0 0 0"
               width="800" height="800" mark="random" markrgb="0.3 0.4 0.5"/>
    <texture builtin="flat" height="1278" mark="cross" markrgb="1 1 1" name="texgeom" random="0.01" rgb1="0.8 0.6 0.4" rgb2="0.8 0.6 0.4" type="cube" width="127"/>
    <texture builtin="checker" height="100" name="texplane" rgb1=".1 .3 .2" rgb2=".2 .5 .3" type="2d" width="100" mark="edge" markrgb=".2 .5 .3"/>
    <texture name="hilltexture" file="OutdoorGrassFloorD.png" height="20" type="2d" width="20"/>
    <material name="MatPlane" reflectance="0.5" shininess="1" specular="1" texrepeat="100 20" texture="texplane"/>
    <material name="geom" texture="texgeom" texuniform="true"/>
    <hfield name="hill" file="hfield_flat_rect.png" size="100 20 1.0 0.1"/>
  </asset>
  <worldbody>
    <light cutoff="100" diffuse="1 1 1" dir="-0 0 -1.3" directional="true" exponent="1" pos="0 0 1.3" specular=".1 .1 .1"/>
    <!--<geom conaffinity="1" condim="3" material="MatPlane" name="floor" pos="0 0 0" rgba="0.8 0.9 0.8 1" size="40 40 40" type="plane"/>-->
    <geom name='floor' material="MatPlane" pos='0 0 0' size='100 20 0.1' type='hfield' conaffinity='1' rgba='0.8 0.9 0.8 1' condim='3' hfield="hill"/>
    <body name="torso" pos="0 0 0.2">
      <camera name="track" mode="trackcom" pos="0 -3 0.3" xyaxes="1 0 0 0 0 1"/>
      <geom name="torso_geom" fromto="-0.14 0 0 0.14 0 0" size="0.02" mass="1.4" type="capsule"/>
      
      <joint armature="0" damping="0" limited="false" margin="0.01" name="root" pos="0 0 0" type="free"/>

      <body name="front_left_leg" pos="0.06 0 0">
        <geom fromto="0.0 0.0 0.0 0.06 0.06 0.0" name="aux_fl_geom" size="0.015" type="capsule"/>
        <body name="aux_fl" pos="0.06 0.06 0">
          <joint axis="0 0 1" name="coxa_fl" pos="0.0 0.0 0.0" range="-30 30" type="hinge"/>
          <geom fromto="0.0 0.0 0.0 0.03676 0.03676 0.0" name="coxa_fl_geom" size="0.015" mass="0.015" type="capsule"/>
          <body pos="0.03676 0.03676 0">
            <joint axis="-1 1 0" name="femur_fl" pos="0.0 0.0 0.0" range="-30 30" type="hinge"/>
            <geom fromto="0.0 0.0 0.0 0.0466 0.0466 0.0" name="femur_fl_geom" size="0.015" mass="0.07" type="capsule"/>
             <body pos="0.0466 0.0466 -0.015">
                <joint axis="-1 1 0" name="tibia_fl" pos="0.0 0.0 0.0" range="30 70" type="hinge"/>
                <geom fromto="0.0 0.0 0.0 0.0636 0.0636 -0.1" name="tibia_fl_geom" size="0.015" mass="0.08" type="capsule"/>
                <site name="foot_fl" pos="0.0636 0.0636 -0.1" size=".015" type="sphere" rgba="1.0 1.0 1.0 1.0"/>
             </body>
          </body>
        </body>
      </body>

      <body name="front_right_leg" pos="0.06 0 0">
        <geom fromto="0.0 0.0 0.0 0.06 -0.06 0.0" name="aux_fr_geom" size="0.015" type="capsule"/>
        <body name="aux_fr" pos="0.06 -0.06 0">
          <joint axis="0 0 1" name="coxa_fr" pos="0.0 0.0 0.0" range="-30 30" type="hinge"/>
          <geom fromto="0.0 0.0 0.0 0.03676 -0.03676 0.0" name="coxa_fr_geom" size="0.015" mass="0.015" type="capsule"/>
          <body pos="0.03676 -0.03676 0">
            <joint axis="1 1 0" name="femur_fr" pos="0.0 0.0 0.0" range="-30 30" type="hinge"/>
            <geom fromto="0.0 0.0 0.0 0.0466 -0.0466 0.0" name="femur_fr_geom" size="0.015" mass="0.07" type="capsule"/>
             <body pos="0.0466 -0.0466 -0.015">
                <joint axis="1 1 0" name="tibia_fr" pos="0.0 0.0 0.0" range="30 70" type="hinge"/>
                <geom fromto="0.0 0.0 0.0 0.0636 -0.0636 -0.1" name="tibia_fr_geom" size="0.015" mass="0.08" type="capsule"/>
                <site name="foot_fr" pos="0.0636 -0.0636 -0.1" size=".015" type="sphere" rgba="1.0 1.0 1.0 1.0"/>
            </body>
          </body>
        </body>
      </body>

      <body name="middle_left_leg" pos="0 0 0">
        <geom fromto="0.0 0.0 0.0 0.0 0.1 0.0" name="aux_3_geom" size="0.015" type="capsule"/> 
        <body name="aux_ml" pos="0 0.1 0">
        <joint axis="0 0 1" name="coxa_ml" pos="0.0 0.0 0.0" range="-30 30" type="hinge" />
          <geom fromto="0.0 0.0 0.0 0.0 0.052 0.0" name="coxa_ml_geom" size="0.015" mass="0.015" type="capsule"/>
          <body pos="0.0 0.052 0">
            <joint axis="-1 0 0" name="femur_ml" pos="0.0 0.0 0.0" range="-30 30" type="hinge"/>
            <geom fromto="0.0 0.0 0.0 0.0 0.066 0" name="femur_ml_geom" size="0.015" mass="0.07" type="capsule"/>
             <body pos="0.0 0.066 -0.015">
                <joint axis="-1 0 0" name="tibia_ml" pos="0.0 0.0 0.0" range="30 70" type="hinge"/>
                <geom fromto="0.0 0.0 0.0 0.0 0.09 -0.10" name="tibia_ml_geom" size="0.015" mass="0.8" type="capsule"/>
                <site name="foot_ml" pos="0 0.09 -0.1" size=".015" type="sphere" rgba="1.0 1.0 1.0 1.0"/>
            </body>
          </body>
        </body>
      </body>

      <body name="middle_right_leg" pos="0 0 0">
        <geom fromto="0.0 0.0 0.0 0 -0.1 0.0" name="aux_mr_geom" size="0.015" type="capsule"/>
        <body name="aux_mr" pos="0 -0.1 0">
        <joint axis="0 0 1" name="coxa_mr" pos="0.0 0.0 0.0" range="-30 30" type="hinge"/>
          <geom fromto="0.0 0.0 0.0 0.0 -0.052 0.0" name="coxa_mr_geom" size="0.015" mass="0.015" type="capsule"/>
          <body pos="0.0 -0.052 0">
            <joint axis="1 0 0" name="femur_mr" pos="0.0 0.0 0.0" range="-30 30" type="hinge"/>
            <geom fromto="0.0 0.0 0.0 0.0 -0.066 0.0" name="femur_mr_geom" size="0.015" mass="0.07" type="capsule"/>
             <body pos="0.0 -0.066 -0.015">
                <joint axis="1 0 0" name="tibia_mr" pos="0.0 0.0 0.0" range="30 70" type="hinge"/>
                <geom fromto="0.0 0.0 0.0 0.0 -0.09 -0.1" name="tibia_mr_geom" size="0.015" mass="0.08" type="capsule"/>
                <site name="foot_mr" pos="0 -0.09 -0.1" size=".015" type="sphere" rgba="1.0 1.0 1.0 1.0"/>
            </body>
          </body>
        </body>
      </body>

      <body name="hind_left_leg" pos="-0.06 0 0">
        <geom fromto="0.0 0.0 0.0 -0.06 0.06 0.0" name="aux_hl_geom" size="0.015" type="capsule"/>
        <body name="aux_hl" pos="-0.06 0.06 0">
        <joint axis="0 0 1" name="coxa_hl" pos="0.0 0.0 0.0" range="-30 30" type="hinge"/>
          <geom fromto="0.0 0.0 0.0 -0.03676 0.03676 0.0" name="coxa_hl_geom" size="0.015" mass="0.015" type="capsule"/>
          <body pos="-0.03676 0.03676 0">
            <joint axis="-1 -1 0" name="femur_hl" pos="0.0 0.0 0.0" range="-30 30" type="hinge"/>
            <geom fromto="0.0 0.0 0.0 -0.0466 0.0466 0" name="femur_hl_geom" size="0.015" mass="0.07"  type="capsule"/>
             <body pos="-0.0466 0.04660 -0.015">
                <joint axis="-1 -1 0" name="tibia_hl" pos="0.0 0.0 0.0" range="30 70" type="hinge"/>
                <geom fromto="0.0 0.0 0.0 -0.0636 0.0636 -0.1" name="tibia_hl_geom" size="0.015" mass="0.08" type="capsule"/>
               <site name="foot_hl" pos="-0.0636 0.0636 -0.1" size=".015" type="sphere" rgba="1.0 1.0 1.0 1.0"/>
            </body>
          </body>
        </body>
      </body>

      <body name="hind_right_leg" pos="-0.06 0 0">
        <geom fromto="0.0 0.0 0.0 -0.06 -0.06 0.0" name="aux_hr_geom" size="0.015" type="capsule"/>
        <body name="aux_hr" pos="-0.06 -0.06 0">
        <joint axis="0 0 1" name="coxa_hr" pos="0.0 0.0 0.0" range="-30 30" type="hinge"/>
          <geom fromto="0.0 0.0 0.0 -0.03676 -0.03676 0.0" name="coxa_hr_geom" size="0.015" mass="0.015" type="capsule"/>
          <body pos="-0.03676 -0.03676 0">
            <joint axis="1 -1 0" name="femur_hr" pos="0.0 0.0 0.0" range="-30 30" type="hinge"/>
            <geom fromto="0.0 0.0 0.0 -0.0466 -0.0466 0.0" name="femur_hr_geom" size="0.015" mass="0.07" type="capsule"/>
             <body pos="-0.0466 -0.0466 -0.015">
                <joint axis="1 -1 0" name="tibia_hr" pos="0.0 0.0 0.0" range="30 70" type="hinge"/>
                <geom fromto="0.0 0.0 0.0 -0.0636 -0.0636 -0.1" name="tibia_hr_geom" size="0.015" mass="0.08" type="capsule"/>
               <site name="foot_hr" pos="-0.0636 -0.0636 -0.1" size=".015" type="sphere" rgba="1.0 1.0 1.0 1.0"/>
            </body>
          </body>
        </body>
      </body>
      
    </body>
  </worldbody>
  
  <sensor>
     <touch name="gc_fl" site="foot_fl" />
  </sensor>

  <sensor>
     <touch name="gc_fr" site="foot_fr" />
  </sensor>

  <sensor>
     <touch name="gc_ml" site="foot_ml" />
  </sensor>

  <sensor>
     <touch name="gc_mr" site="foot_mr" />
  </sensor>

  <sensor>
     <touch name="gc_hl" site="foot_hl" />
  </sensor>

  <sensor>
     <touch name="gc_hr" site="foot_hr" />
  </sensor>
  
  <actuator>
    <motor joint="coxa_fl" ctrllimited="true" ctrlrange="-1.0 1.0" gear="150"/>
    <motor joint="femur_fl" ctrllimited="true" ctrlrange="-1.0 1.0" gear="150"/>
    <motor joint="tibia_fl" ctrllimited="true" ctrlrange="-1.0 1.0" gear="150"/>
    <motor joint="coxa_fr" ctrllimited="true" ctrlrange="-1.0 1.0" gear="150"/>
    <motor joint="femur_fr" ctrllimited="true" ctrlrange="-1.0 1.0" gear="150"/>
    <motor joint="tibia_fr" ctrllimited="true" ctrlrange="-1.0 1.0" gear="150"/>
    <motor joint="coxa_ml" ctrllimited="true" ctrlrange="-1.0 1.0" gear="150"/>
    <motor joint="femur_ml" ctrllimited="true" ctrlrange="-1.0 1.0" gear="150"/>
    <motor joint="tibia_ml" ctrllimited="true" ctrlrange="-1.0 1.0" gear="150"/>
    <motor joint="coxa_mr" ctrllimited="true" ctrlrange="-1.0 1.0" gear="150"/>
    <motor joint="femur_mr" ctrllimited="true" ctrlrange="-1.0 1.0" gear="150"/>
    <motor joint="tibia_mr" ctrllimited="true" ctrlrange="-1.0 1.0" gear="150"/>
    <motor joint="coxa_hl" ctrllimited="true" ctrlrange="-1.0 1.0" gear="150"/>
    <motor joint="femur_hl" ctrllimited="true" ctrlrange="-1.0 1.0" gear="150"/>
    <motor joint="tibia_hl" ctrllimited="true" ctrlrange="-1.0 1.0" gear="150"/>
    <motor joint="coxa_hr" ctrllimited="true" ctrlrange="-1.0 1.0" gear="150"/>
    <motor joint="femur_hr" ctrllimited="true" ctrlrange="-1.0 1.0" gear="150"/>
    <motor joint="tibia_hr" ctrllimited="true" ctrlrange="-1.0 1.0" gear="150"/>
  </actuator>
  
</mujoco>
